<?xml version="1.0" encoding="utf-8"?>
<!-- This URDF was automatically created by SolidWorks to URDF Exporter! Originally created by Stephen Brawner (brawner@gmail.com) 
     Commit Version: 1.6.0-4-g7f85cfe  Build Version: 1.6.7995.38578
     For more information, please see http://wiki.ros.org/sw_urdf_exporter -->
<robot
  name="wheel_leg_v6">
  <link
    name="base_link">
    <inertial>
      <origin
        xyz="0.0458054888502351 -6.39335121090792E-05 0.0213461234505319"
        rpy="0 0 0" />
      <mass
        value="3.010" />
      <inertia
        ixx="0.027943"
        ixy="0.000000074"
        ixz="-0.000006675"
        iyy="0.030335"
        iyz="0.0020097"
        izz="0.008610" />
    </inertial>
    <visual>
      <origin
        xyz="0 0 0"
        rpy="0 0 0" />
      <geometry>
        <mesh
          filename="../meshes/base_link.STL" />
      </geometry>
      <material
        name="">
        <color
          rgba="0.752941176470588 0.752941176470588 0.752941176470588 1" />
      </material>
    </visual>
    <!-- <collision>
      <origin
        xyz="0 0 0"
        rpy="0 0 0" />
      <geometry>
        <mesh
          filename="../meshes/base_link.STL" />
      </geometry>
    </collision> -->
    <collision>
      <origin rpy="0 0 0" xyz="0.035 0 0.04"/>
      <geometry>
        <box size="0.3 0.4 0.19"/>
      </geometry>
    </collision>
  </link>
  <link
    name="left_leg_1">
    <inertial>
      <origin
        xyz="0.0568212315420159 0.000357099440417466 0.0991448296874102"
        rpy="0 0 0" />
      <mass
        value="3.3100388" />
      <inertia
        ixx="0.0104422"
        ixy="-0.0004575"
        ixz="0.0002715"
        iyy="0.0228379"
        iyz="0.0002194"
        izz="0.0225252" />
    </inertial>
    <visual>
      <origin
        xyz="0 0 0"
        rpy="0 0 0" />
      <geometry>
        <mesh
          filename="../meshes/left_leg_1.STL" />
      </geometry>
      <material
        name="">
        <color
          rgba="0.752941176470588 0.752941176470588 0.752941176470588 1" />
      </material>
    </visual>
    <!-- <collision>
      <origin
        xyz="0 0 0"
        rpy="0 0 0" />
      <geometry>
        <mesh
          filename="../meshes/left_leg_1.STL" />
      </geometry>
    </collision> -->
  </link>
  <joint
    name="joint_left_leg_1"
    type="revolute">
    <origin
      xyz="0.145175 0.0900000000000078 0.0174103182708737"
      rpy="-1.5707963267949 0 1.5707963267949" />
    <parent
      link="base_link" />
    <child
      link="left_leg_1" />
    <axis
      xyz="0 0 -1" />
    <limit
      lower="-3.14"
      upper="3.14"
      effort="54"
      velocity="25" />
  </joint>
  <link
    name="left_leg_2">
    <inertial>
      <origin
        xyz="-0.00607993980725574 -0.0192970444675853 -0.074379759761367"
        rpy="0 0 0" />
      <mass
        value="1.1671522" />
      <inertia
        ixx="0.0023562"
        ixy="0.0005037"
        ixz="-0.0008166"
        iyy="0.0034736"
        iyz="0.0000849"
        izz="0.0032638" />
    </inertial>
    <visual>
      <origin
        xyz="0 0 0"
        rpy="0 0 0" />
      <geometry>
        <mesh
          filename="../meshes/left_leg_2.STL" />
      </geometry>
      <material
        name="">
        <color
          rgba="0.752941176470588 0.752941176470588 0.752941176470588 1" />
      </material>
    </visual>
    <!-- <collision>
      <origin
        xyz="0 0 0"
        rpy="0 0 0" />
      <geometry>
        <mesh
          filename="../meshes/left_leg_2.STL" />
      </geometry>
    </collision> -->
  </link>
  <joint
    name="joint_left_leg_2"
    type="revolute">
    <origin
      xyz="0.048749999999998 0 0.0600000000000813"
      rpy="3.14159265358979 1.5707963267949 0" />
    <parent
      link="left_leg_1" />
    <child
      link="left_leg_2" />
    <axis
      xyz="0 0 -1" />
    <limit
      lower="-3.14"
      upper="3.14"
      effort="45"
      velocity="25" />
  </joint>
  <link
    name="left_leg_3">
    <inertial>
      <origin
        xyz="0.0930515283509998 0.00386085078700438 0.0206210506776906"
        rpy="0 0 0" />
      <mass
        value="0.8312407" />
      <inertia
        ixx="0.0039571"
        ixy="0.0005622"
        ixz="0.0020165"
        iyy="0.0049550"
        iyz="-0.0009617"
        izz="0.0017781" />
    </inertial>
    <visual>
      <origin
        xyz="0 0 0"
        rpy="0 0 0" />
      <geometry>
        <mesh
          filename="../meshes/left_leg_3.STL" />
      </geometry>
      <material
        name="">
        <color
          rgba="0.752941176470588 0.752941176470588 0.752941176470588 1" />
      </material>
    </visual>
    <!-- <collision>
      <origin
        xyz="0 0 0"
        rpy="0 0 0" />
      <geometry>
        <mesh
          filename="../meshes/left_leg_3.STL" />
      </geometry>
    </collision> -->
    <collision>
      <origin rpy="0 0 0" xyz="0.085 0 0.018"/>
      <geometry>
        <box size="0.20 0.055 0.05"/>
      </geometry>
    </collision>
  </link>
  <joint
    name="joint_left_leg_3"
    type="revolute">
    <origin
      xyz="-0.000423730769543607 -0.119999251882008 -0.095250000000001"
      rpy="-3.14159265358979 0 -1.5" />
    <parent
      link="left_leg_2" />
    <child
      link="left_leg_3" />
    <axis
      xyz="0 0 1" />
    <limit
      lower="-3.14"
      upper="3.14"
      effort="45"
      velocity="25" />
  </joint>
  <link
    name="left_leg_4">
    <inertial>
      <origin
        xyz="0.00048826255191825 -0.00046455542259044 0.0620525592666707"
        rpy="0 0 0" />
      <mass
        value="0.2412764" />
      <inertia
        ixx="0.0002102"
        ixy="6.00389611396174E-17"
        ixz="-3.48603090596418E-16"
        iyy="0.0003907"
        iyz="-0.0000527"
        izz="0.0002161" />
    </inertial>
    <visual>
      <origin
        xyz="0 0 0"
        rpy="0 0 0" />
      <geometry>
        <mesh
          filename="../meshes/left_leg_4.STL" />
      </geometry>
      <material
        name="">
        <color
          rgba="0.752941176470588 0.752941176470588 0.752941176470588 1" />
      </material>
    </visual>
    <!-- <collision>
      <origin
        xyz="0 0 0"
        rpy="0 0 0" />
      <geometry>
        <mesh
          filename="../meshes/left_leg_4.STL" />
      </geometry>
    </collision> -->
    <collision>
      <origin rpy="0 0 0" xyz="0 0 0.065"/>
      <geometry>
        <cylinder length="0.028" radius="0.062"/>
      </geometry>
    </collision>
  </link>
  <joint
    name="joint_left_leg_4"
    type="revolute">
    <origin
      xyz="0.179793722057134 0.00760732887062751 -0.00700000000000042"
      rpy="0 0 0" />
    <parent
      link="left_leg_3" />
    <child
      link="left_leg_4" />
    <axis
      xyz="0 0 1" />
    <limit
      lower="-999999"
      upper="999999"
      effort="45"
      velocity="20" />
  </joint>
  <link
    name="right_leg_1">
    <inertial>
      <origin
        xyz="0.0568496416845237 -0.000340466840961604 0.0990093118523285"
        rpy="0 0 0" />
      <mass
        value="3.3100388" />
      <inertia
        ixx="0.0104422"
        ixy="0.0004871"
        ixz="0.0000346"
        iyy="0.0226956"
        iyz="-0.0002226"
        izz="0.0226674" />
    </inertial>
    <visual>
      <origin
        xyz="0 0 0"
        rpy="0 0 0" />
      <geometry>
        <mesh
          filename="../meshes/right_leg_1.STL" />
      </geometry>
      <material
        name="">
        <color
          rgba="0.752941176470588 0.752941176470588 0.752941176470588 1" />
      </material>
    </visual>
    <!-- <collision>
      <origin
        xyz="0 0 0"
        rpy="0 0 0" />
      <geometry>
        <mesh
          filename="../meshes/right_leg_1.STL" />
      </geometry>
    </collision> -->
  </link>
  <joint
    name="joint_right_leg_1"
    type="revolute">
    <origin
      xyz="0.145175 -0.0900000000000078 0.0174103182708737"
      rpy="1.5707963267949 0 -1.5707963267949" />
    <parent
      link="base_link" />
    <child
      link="right_leg_1" />
    <axis
      xyz="0 0 -1" />
    <limit
      lower="-0.7854"
      upper="0.785398"
      effort="54"
      velocity="25" />
  </joint>
  <link
    name="right_leg_2">
    <inertial>
      <origin
        xyz="-0.00644318870107519 0.0206429726697923 -0.0740246638796309"
        rpy="0 0 0" />
      <mass
        value="1.1671522" />
      <inertia
        ixx="0.0026513"
        ixy="-0.0008219"
        ixz="-0.0006643"
        iyy="0.0033326"
        iyz="-0.0002584"
        izz="0.0032647" />
    </inertial>
    <visual>
      <origin
        xyz="0 0 0"
        rpy="0 0 0" />
      <geometry>
        <mesh
          filename="../meshes/right_leg_2.STL" />
      </geometry>
      <material
        name="">
        <color
          rgba="0.752941176470588 0.752941176470588 0.752941176470588 1" />
      </material>
    </visual>
    <!-- <collision>
      <origin
        xyz="0 0 0"
        rpy="0 0 0" />
      <geometry>
        <mesh
          filename="../meshes/right_leg_2.STL" />
      </geometry>
    </collision> -->
  </link>
  <joint
    name="joint_right_leg_2"
    type="revolute">
    <origin
      xyz="0.0487499999999984 0 0.0600000000000223"
      rpy="3.14159265358979 1.5707963267949 0" />
    <parent
      link="right_leg_1" />
    <child
      link="right_leg_2" />
    <axis
      xyz="0 0 1" />
    <limit
      lower="-3.14"
      upper="3.14"
      effort="45"
      velocity="25" />
  </joint>
  <link
    name="right_leg_3">
    <inertial>
      <origin
        xyz="0.0918675216209679 -0.00380518566196797 0.0203188921624513"
        rpy="0 0 0" />
      <mass
        value="0.8312407" />
      <inertia
        ixx="0.0030318"
        ixy="-0.0006761"
        ixz="0.0023810"
        iyy="0.0051644"
        iyz="0.0011342"
        izz="0.0024939" />
    </inertial>
    <visual>
      <origin
        xyz="0 0 0"
        rpy="0 0 0" />
      <geometry>
        <mesh
          filename="../meshes/right_leg_3.STL" />
      </geometry>
      <material
        name="">
        <color
          rgba="0.752941176470588 0.752941176470588 0.752941176470588 1" />
      </material>
    </visual>
    <!-- <collision>
      <origin
        xyz="0 0 0"
        rpy="0 0 0" />
      <geometry>
        <mesh
          filename="../meshes/right_leg_3.STL" />
      </geometry>
    </collision> -->
    <collision>
      <origin rpy="0 0 0" xyz="0.085 0 0.018"/>
      <geometry>
        <box size="0.20 0.055 0.05"/>
      </geometry>
    </collision>
  </link>
  <joint
    name="joint_right_leg_3"
    type="revolute">
    <origin
      xyz="-0.00042373076960267 0.119999251882073 -0.0952499999999933"
      rpy="3.14159265358979 0 1.5" />
    <parent
      link="right_leg_2" />
    <child
      link="right_leg_3" />
    <axis
      xyz="0 0 -1" />
    <limit
      lower="-3.14"
      upper="3.14"
      effort="45"
      velocity="25" />
  </joint>
  <link
    name="right_leg_4">
    <inertial>
      <origin
        xyz="0.000488261537471502 0.000464550609021064 0.0619170720242325"
        rpy="0 0 0" />
      <mass
        value="0.2412764" />
      <inertia
        ixx="0.0002102"
        ixy="-3.31410499465468E-18"
        ixz="3.54247770541187E-16"
        iyy="0.0003907"
        iyz="0.0000527"
        izz="0.0002161" />
    </inertial>
    <visual>
      <origin
        xyz="0 0 0"
        rpy="0 0 0" />
      <geometry>
        <mesh
          filename="../meshes/right_leg_4.STL" />
      </geometry>
      <material
        name="">
        <color
          rgba="0.752941176470588 0.752941176470588 0.752941176470588 1" />
      </material>
    </visual>
    <!-- <collision>
      <origin
        xyz="0 0 0"
        rpy="0 0 0" />
      <geometry>
        <mesh
          filename="../meshes/right_leg_4.STL" />
      </geometry>
    </collision> -->
    <collision>
      <origin rpy="0 0 0" xyz="0 0 0.065"/>
      <geometry>
        <cylinder length="0.028" radius="0.062"/>
      </geometry>
    </collision>
  </link>
  <joint
    name="joint_right_leg_4"
    type="revolute">
    <origin
      xyz="0.179793723071581 -0.00760732405705766 -0.00700000000000037"
      rpy="0 0 0" />
    <parent
      link="right_leg_3" />
    <child
      link="right_leg_4" />
    <axis
      xyz="0 0 1" />
    <limit
      lower="-999999"
      upper="999999"
      effort="45"
      velocity="20" />
  </joint>
</robot>