<?xml version="1.0" encoding="utf-8"?>
<!-- This URDF was automatically created by SolidWorks to URDF Exporter! Originally created by Stephen Brawner (brawner@gmail.com) 
     Commit Version: 1.6.0-4-g7f85cfe  Build Version: 1.6.7995.38578
     For more information, please see http://wiki.ros.org/sw_urdf_exporter -->
<robot
  name="wheel_leg_v3">
  <link
    name="base_link">
    <inertial>
      <origin
        xyz="0.0458054888502217 -6.39335121090793E-05 0.0213461234505328"
        rpy="0 0 0" />
      <mass
        value="3.010" />
      <inertia
        ixx="0.027943"
        ixy="0.000000074"
        ixz="-0.000006675"
        iyy="0.030335"
        iyz="0.0020097"
        izz="0.008610" />
    </inertial>
    <visual>
      <origin
        xyz="0 0 0"
        rpy="0 0 0" />
      <geometry>
        <mesh
          filename="../meshes/base_link.STL" />      </geometry>
      <material
        name="">
        <color
          rgba="0.752941176470588 0.752941176470588 0.752941176470588 1" />
      </material>
    </visual>
    <collision>
      <origin
        xyz="0 0 0"
        rpy="0 0 0" />
      <geometry>
        <mesh
          filename="../meshes/base_link.STL" />
      </geometry>
    </collision>
  </link>
  <link
    name="left_roll_link">
    <inertial>
      <origin
        xyz="0.0568212315414509 0.000357099440436381 0.0991448296838704"
        rpy="0 0 0" />
      <mass
        value="3.3100388" />
      <inertia
        ixx="0.0104422"
        ixy="-0.0004575"
        ixz="0.0002715"
        iyy="0.0228379"
        iyz="0.0002194"
        izz="0.0225252" />
    </inertial>
    <visual>
      <origin
        xyz="0 0 0"
        rpy="0 0 0" />
      <geometry>
        <mesh
          filename="../meshes/left_roll_link.STL" />
      </geometry>
      <material
        name="">
        <color
          rgba="0.752941176470588 0.752941176470588 0.752941176470588 1" />
      </material>
    </visual>
    <collision>
      <origin
        xyz="0 0 0"
        rpy="0 0 0" />
      <geometry>
        <mesh
          filename="../meshes/left_roll_link.STL" />
      </geometry>
    </collision>
  </link>
  <joint
    name="left_roll_joint"
    type="revolute">
    <origin
      xyz="0.14518 0.09 0.01741"
      rpy="-1.5708 0 1.5708" />
    <parent
      link="base_link" />
    <child
      link="left_roll_link" />
    <axis
      xyz="0 0 -1" />
    <limit
      lower="-3.14"
      upper="3.14"
      effort="45"
      velocity="25" />
  </joint>
  <link
    name="left_pitch_link">
    <inertial>
      <origin
        xyz="-0.0193714307645352 0.00583988814641517 0.0743796587348333"
        rpy="0 0 0" />
      <mass
        value="1.1671522" />
      <inertia
        ixx="0.0023562"
        ixy="0.0005037"
        ixz="-0.0008166"
        iyy="0.0034736"
        iyz="0.0000849"
        izz="0.0032638" />
    </inertial>
    <visual>
      <origin
        xyz="0 0 0"
        rpy="0 0 0" />
      <geometry>
        <mesh
          filename="../meshes/left_pitch_link.STL" />
      </geometry>
      <material
        name="">
        <color
          rgba="0.752941176470588 0.752941176470588 0.752941176470588 1" />
      </material>
    </visual>
    <collision>
      <origin
        xyz="0 0 0"
        rpy="0 0 0" />
      <geometry>
        <mesh
          filename="../meshes/left_pitch_link.STL" />
      </geometry>
    </collision>
  </link>
  <joint
    name="left_pitch_joint"
    type="revolute">
    <origin
      xyz="0.04875 0 0.06"
      rpy="-3.1416 1.5708 3.1416" />
    <parent
      link="left_roll_link" />
    <child
      link="left_pitch_link" />
    <axis
      xyz="0 0 -1" />
    <limit
      lower="-3.14"
      upper="3.14"
      effort="45"
      velocity="25" />
  </joint>
  <link
    name="left_knee_link">
    <inertial>
      <origin
        xyz="0.0489590999646854 0.0787262079334732 0.0206210506519268"
        rpy="0 0 0" />
      <mass
        value="0.8312407" />
      <inertia
        ixx="0.0039571"
        ixy="0.0005622"
        ixz="0.0020165"
        iyy="0.0049550"
        iyz="-0.0009617"
        izz="0.0017781" />
    </inertial>
    <visual>
      <origin
        xyz="0 0 0"
        rpy="0 0 0" />
      <geometry>
        <mesh
          filename="../meshes/left_knee_link.STL" />
      </geometry>
      <material
        name="">
        <color
          rgba="0.752941176470588 0.752941176470588 0.752941176470588 1" />
      </material>
    </visual>
    <collision>
      <origin
        xyz="0 0 0"
        rpy="0 0 0" />
      <geometry>
        <mesh
          filename="../meshes/left_knee_link.STL" />
      </geometry>
    </collision>
  </link>
  <joint
    name="left_knee_joint"
    type="revolute">
    <origin
      xyz="-0.099175 0.06756 0.095249"
      rpy="0 0 0" />
    <parent
      link="left_pitch_link" />
    <child
      link="left_knee_link" />
    <axis
      xyz="0 0 1" />
    <limit
      lower="-3.14"
      upper="3.14"
      effort="45"
      velocity="25" />
  </joint>
  <link
    name="left_wheel_link">
    <inertial>
      <origin
        xyz="-0.000118337892257347 0.000127549834933571 0.0620525592666707"
        rpy="0 0 0" />
      <mass
        value="0.2412764" />
      <inertia
        ixx="0.0002102"
        ixy="6.00389611396174E-17"
        ixz="-3.48603090596418E-16"
        iyy="0.0003907"
        iyz="-0.0000527"
        izz="0.0002161" />
    </inertial>
    <visual>
      <origin
        xyz="0 0 0"
        rpy="0 0 0" />
      <geometry>
        <mesh
          filename="../meshes/left_wheel_link.STL" />
      </geometry>
      <material
        name="">
        <color
          rgba="0.752941176470588 0.752941176470588 0.752941176470588 1" />
      </material>
    </visual>
    <collision>
      <origin
        xyz="0 0 0"
        rpy="0 0 0" />
      <geometry>
        <mesh
          filename="../meshes/left_wheel_link.STL" />
      </geometry>
    </collision>
  </link>
  <joint
    name="left_wheel_joint"
    type="revolute">
    <origin
      xyz="0.095476 0.15254 -0.007"
      rpy="0 0 0" />
    <parent
      link="left_knee_link" />
    <child
      link="left_wheel_link" />
    <axis
      xyz="0 0 1" />
    <limit
      lower="-999999"
      upper="999999"
      effort="15"
      velocity="20" />
  </joint>
  <link
    name="right_roll_link">
    <inertial>
      <origin
        xyz="0.0568212315414515 -0.00285777729501922 0.0991448296838704"
        rpy="0 0 0" />
      <mass
        value="3.3100388" />
      <inertia
        ixx="0.0104422"
        ixy="0.0004871"
        ixz="0.0000346"
        iyy="0.0226956"
        iyz="-0.0002226"
        izz="0.0226674" />
    </inertial>
    <visual>
      <origin
        xyz="0 0 0"
        rpy="0 0 0" />
      <geometry>
        <mesh
          filename="../meshes/right_roll_link.STL" />
      </geometry>
      <material
        name="">
        <color
          rgba="0.752941176470588 0.752941176470588 0.752941176470588 1" />
      </material>
    </visual>
    <collision>
      <origin
        xyz="0 0 0"
        rpy="0 0 0" />
      <geometry>
        <mesh
          filename="../meshes/right_roll_link.STL" />
      </geometry>
    </collision>
  </link>
  <joint
    name="right_roll_joint"
    type="revolute">
    <origin
      xyz="0.14518 -0.09 0.01741"
      rpy="1.5708 0 -1.5708" />
    <parent
      link="base_link" />
    <child
      link="right_roll_link" />
    <axis
      xyz="0 0 -1" />
    <limit
      lower="-3.14"
      upper="3.14"
      effort="45"
      velocity="25" />
  </joint>
  <link
    name="right_pitch_link">
    <inertial>
      <origin
        xyz="-0.019371116603951 -0.0058392364337765 0.0621397825516607"
        rpy="0 0 0" />
      <mass
        value="1.1671522" />
      <inertia
        ixx="0.0026513"
        ixy="-0.0008219"
        ixz="-0.0006643"
        iyy="0.0033326"
        iyz="-0.0002584"
        izz="0.0032647" />
    </inertial>
    <visual>
      <origin
        xyz="0 0 0"
        rpy="0 0 0" />
      <geometry>
        <mesh
          filename="../meshes/right_pitch_link.STL" />
      </geometry>
      <material
        name="">
        <color
          rgba="0.752941176470588 0.752941176470588 0.752941176470588 1" />
      </material>
    </visual>
    <collision>
      <origin
        xyz="0 0 0"
        rpy="0 0 0" />
      <geometry>
        <mesh
          filename="../meshes/right_pitch_link.STL" />
      </geometry>
    </collision>
  </link>
  <joint
    name="right_pitch_joint"
    type="revolute">
    <origin
      xyz="0.061 0 0.06"
      rpy="0 1.5708 0" />
    <parent
      link="right_roll_link" />
    <child
      link="right_pitch_link" />
    <axis
      xyz="0 0 1" />
    <limit
      lower="-3.14"
      upper="3.14"
      effort="45"
      velocity="25" />
  </joint>
  <link
    name="right_knee_link">
    <inertial>
      <origin
        xyz="0.0489590999717842 -0.0787262079412891 -0.0206210506536015"
        rpy="0 0 0" />
      <mass
        value="0.8312407" />
      <inertia
        ixx="0.0030318"
        ixy="-0.0006761"
        ixz="0.0023810"
        iyy="0.0051644"
        iyz="0.0011342"
        izz="0.0024939" />
    </inertial>
    <visual>
      <origin
        xyz="0 0 0"
        rpy="0 0 0" />
      <geometry>
        <mesh
          filename="../meshes/right_knee_link.STL" />
      </geometry>
      <material
        name="">
        <color
          rgba="0.752941176470588 0.752941176470588 0.752941176470588 1" />
      </material>
    </visual>
    <collision>
      <origin
        xyz="0 0 0"
        rpy="0 0 0" />
      <geometry>
        <mesh
          filename="../meshes/right_knee_link.STL" />
      </geometry>
    </collision>
  </link>
  <joint
    name="right_knee_joint"
    type="revolute">
    <origin
      xyz="-0.099175 -0.06756 0.123"
      rpy="0 0 0" />
    <parent
      link="right_pitch_link" />
    <child
      link="right_knee_link" />
    <axis
      xyz="0 0 -1" />
    <limit
      lower="-3.14"
      upper="3.14"
      effort="45"
      velocity="25" />
  </joint>
  <link
    name="right_wheel_link">
    <inertial>
      <origin
        xyz="-4.44089209850063E-16 9.99200722162641E-16 0.050447440733329"
        rpy="0 0 0" />
      <mass
        value="0.2412764" />
      <inertia
        ixx="0.0002102"
        ixy="-3.31410499465468E-18"
        ixz="3.54247770541187E-16"
        iyy="0.0003907"
        iyz="0.0000527"
        izz="0.0002161" />
    </inertial>
    <visual>
      <origin
        xyz="0 0 0"
        rpy="0 0 0" />
      <geometry>
        <mesh
          filename="../meshes/right_wheel_link.STL" />
      </geometry>
      <material
        name="">
        <color
          rgba="0.752941176470588 0.752941176470588 0.752941176470588 1" />
      </material>
    </visual>
    <collision>
      <origin
        xyz="0 0 0"
        rpy="0 0 0" />
      <geometry>
        <mesh
          filename="../meshes/right_wheel_link.STL" />
      </geometry>
    </collision>
  </link>
  <joint
    name="right_wheel_joint"
    type="revolute">
    <origin
      xyz="0.095357 -0.15267 -0.0435"
      rpy="0 0 0" />
    <parent
      link="right_knee_link" />
    <child
      link="right_wheel_link" />
    <axis
      xyz="0 0 -1" />
    <limit
      lower="-999999"
      upper="999999"
      effort="15"
      velocity="20" />
  </joint>
</robot>